Workbook
Name _ccVersion: 1.74
Name _EBITDAMult: #REF!
Name _FCFMult: #REF!
Name _r: "Formula removed, name can be deleted."
Name _scenchg_count: 1
Name africa: #REF!
Name africa: #REF!
Name africaCountries: #REF!
Name africaCountries: #REF!
Name africaCountries: '[5]MW GEG'!$J$25:$J$26
Name allRegions: #REF!
Name allRegions: #REF!
Name allRegions: #REF!
Name americaRegion: #REF!
Name americaRegion: #REF!
Name americaRegion: #REF!
Name americas: #REF!
Name americas: #REF!
Name americasStates: #REF!
Name americasStates: #REF!
Name americasStates: #REF!
Name APACCountry: [6]APAC!$N$4:$N$1048576
Name APACQ413OperationalStatus: [6]APAC!$W$4:$W$1048576
Name AppVersion: #REF!
Name AppVersion: #REF!
Name asiaPacific: #REF!
Name asiaPacific: #REF!
Name asiaPacificExJapan: #REF!
Name asiaPacificExJapan: #REF!
Name asiaPacificExJapanCountries: #REF!
Name asiaPacificExJapanCountries: #REF!
Name asiaPacificExJapanCountries: '[5]MW GEG'!$J$32:$J$36
Name asiaPacificRegion: #REF!
Name asiaPacificRegion: #REF!
Name asiaPacificRegion: #REF!
Name asiaPacificStates: #REF!
Name asiaPacificStates: #REF!
Name asiaPacificStates: '[5]MW GEG'!$H$28:$H$31
Name australasia: #REF!
Name australasia: #REF!
Name blnImportOK: #REF!
Name BoxPlot: "BoxPlot"
Name BRICS: #REF!
Name BRICS: #REF!
Name BSMethod: 2
Name Bubble: "Bubble"
Name Button_1: "TFT_report_data_share_prices_List"
Name Candlestick: "Candlestick"
Name CashFlowCapitalExpenditureCellular: 0
Name CashFlowCapitalExpenditureOther: 0
Name CashFlowCapitalExpenditurePaging: 0
Name CashFlowCapitalExpenditureTelephone: 0
Name CashFlowCapitalExpenditureWireless: 0
Name CashFlowDividendPaidPreferredStock: 0
Name cc_ReportCurrency: "HKD"
Name cc_ReportCurrencyUnit: "HK$"
Name cc_ReportCurrencyUnitFactor: 1
Name Cellcost_anode: #REF!
Name Cellcost_cathode: #REF!
Name Cellcost_Depreciation_Equip: #REF!

Sheet ROIC Dashboard
B2: Rental economics
C4: Size (GW) | D4: Number of chips | E4: Capex | F4: Rental rate | H4: Utilisation | I4: Annual revenue | J4: Power price | K4: Power costs | L4: Other costs | M4: Gross profit | N4: IRR
B5: Vera Rubin | C5: 1 | D5: ='Vera Rubin'!E52 -> 299376.3 | E5: ='Vera Rubin'!E67 -> 51292.007 | F5: 10 | H5: 0.8 | I5: =F5*8760*H5*D5/1000000 -> 20980.291
B6: GB300 | C6: 1 | D6: ='GB300 '!E52 -> 444444.44 | E6: ='GB300 '!E67 -> 44768.833 | F6: 1 | H6: 0.8 | I6: =F6*8760*H6*D6/1000000 -> 3114.6667 | J6: 50 | K6: =J6*H6*8760/1000 -> 350.4 | L6: 1000 | M6: =I6-K6-L6 -> 1764.2667 | N6: =IRR(P6:U6) -> -0.37551068 | P6: =-E6 -> -44768.833 | Q6: =M6 -> 1764.2667 | R6: =Q6 -> 1764.2667 | S6: =R6 -> 1764.2667 | T6: =S6 -> 1764.2667 | U6: =T6 -> 1764.2667
B7: TPUv7 | C7: 1 | D7: =TPUv7!E54 -> 708923.08 | E7: =TPUv7!E69 -> 27228.225 | F7: 3.5 | H7: 0.8 | I7: =F7*8760*H7*D7/1000000 -> 17388.465 | J7: 50 | K7: =J7*H7*8760/1000 -> 350.4 | L7: 1000 | M7: =I7-K7-L7 -> 16038.065 | N7: =IRR(P7:U7) -> 0.51529252 | P7: =-E7 -> -27228.225 | Q7: =M7 -> 16038.065 | R7: =Q7 -> 16038.065 | S7: =R7 -> 16038.065 | T7: =S7 -> 16038.065 | U7: =T7 -> 16038.065
B8: Trainium3 | C8: 1 | D8: =Trainium3!E53 -> 769230.77 | E8: =Trainium3!E68 -> 20902.74 | F8: 2 | H8: 0.8 | I8: =F8*8760*H8*D8/1000000 -> 10781.538 | J8: 50 | K8: =J8*H8*8760/1000 -> 350.4 | L8: 1000 | M8: =I8-K8-L8 -> 9431.1385 | N8: =IRR(P8:U8) -> 0.35090704 | P8: =-E8 -> -20902.74 | Q8: =M8 -> 9431.1385 | R8: =Q8 -> 9431.1385 | S8: =R8 -> 9431.1385 | T8: =S8 -> 9431.1385 | U8: =T8 -> 9431.1385
B10: Token economics
C12: Size (GW) | D12: Number of chips | E12: Capex | F12: Blended token price | G12: Token volume | H12: Utilisation
B13: Vera Rubin
B14: GB300 | C14: 1 | D14: =D6 -> 444444.44 | E14: =E6 -> 44768.833 | F14: 0.12 | G14: ='Token throughput matrix'!C3 -> 2644 | H14: 0.7 | I14: =(F14/1000000)*(G14*60*60*8760)*D14*H14/1000000 -> 3112.8975 | J14: 50 | K14: =J14*H14*8760/1000 -> 306.6 | L14: 1000 | M14: =I14-K14-L14 -> 1806.2975 | N14: =IRR(P14:U14) -> -0.37168699 | P14: =-E14 -> -44768.833 | Q14: =M14 -> 1806.2975 | R14: =Q14 -> 1806.2975 | S14: =R14 -> 1806.2975 | T14: =S14 -> 1806.2975 | U14: =T14 -> 1806.2975
B15: TPUv7
B16: Trainium3

Sheet Data sources
B2: Token throughput
C3: InferenceX
C4: Mlperf
C5: Nvidia Inference Performance | F5: Inference Performance for Data Center Deep Learning | NVIDIA Developer
B15: GPU rental rates
C16: System Capital Dashboard
C17: Silicon Data benchmarks
C18: AWS
C19: Google
C20: Azure
C21: GPU finder | F21: B300 Cloud Pricing from $6.94/hr (2026) — 5 Providers
B26: Token prices
C27: System Capital Dashboard
C28: Bedrock
C29: Vertex
C30: Foundry
C31: OpenAI
C32: Anthropic

Sheet Conversion
B2: GB300
B3: Size (GW) | C3: 1
B4: Chips | C4: ='GB300 '!E52 -> 444444.44
B5: Price | C5: 1
B6: Utilisation | C6: 0.8
B7: Revenue ($) | C7: =C4*C5*8760*C6 -> 3.1146667e+09
B9: Revenue per watt | C9: =C7/(C3*1000000000) -> 3.1146667
C11: =C5/C9 -> 0.32106164

Sheet Total
B2: Revenue
B14: Capex

Sheet Trainium3
B2: Size Data Center (MW) | C2: 1000 | F2: 10
F3: 1000
B5: 1. IT Hardware
B7: ASICs Per Rack | E7: ='[17]Trainium Rack Cost (64)'!E8 -> 64
B9: Cost Per ASIC | E9: ='[17]Trainium Rack Cost (64)'!D8 -> 5760
B11: HBM Contribution | E11: =(E14*E15) -> 3168
B12: HBM % of Trainium Costs | E12: =E11/E9 -> 0.55
B13: Memory % of of GW Scale Capex | E13: =((E11/1000000*E53)+(E23*E54))/E68 -> 0.15682522
B14: HBM3e GB per Trainium3 chip | E14: 144
B15: Implied Price per GB of HBM3E | E15: 22
B17: ASIC Cost Per Rack ($M) | E17: =(E7*E9)/1000000 -> 0.36864
B18: % of Rack Cost | E18: =E17/E36 -> 0.46212862
B20: Other Rack Costs | E20: =E36-E17 -> 0.42906
B21: % of Rack Cost | E21: =E20/E36 -> 0.53787138
B23: Memory Contribution (Rack Level) | E23: =(E26*E25)/1000000 -> 0.069984
B24: % of ASIC Costs | E24: =E23/E17 -> 0.18984375
B25: GB DDR5 / Rack | E25: =E30/2*512 -> 9216
B26: Price Per GB DDR5 | E26: 7.59375
B28: CPU Contribution | E28: =(E30*E31)/1000000 -> 0.0746496
B29: % of ASIC Costs | E29: =E28/E17 -> 0.2025
B30: CPUs / Rack | E30: 36
B31: Implied Price per CPU | E31: 2073.6
B33: Other Contribution | E33: =E17*E34 -> 0.258048
B34: % of ASIC Costs | E34: 0.7
B36: Total Rack Cost ($M) | E36: ='[17]Trainium Rack Cost (64)'!F21/1000000 -> 0.7977
B38: Power Required Per Rack (kW) | E38: =E7 -> 64
B40: Utilization Rate | E40: 0.75
B42: Annual Power Per Rack (MWh) | E42: =E38*8.76*E40 -> 420.48
B44: Power Usage Effectiveness (PUE) | E44: 1.3
B46: Total Power Per Rack (MWh) | E46: =E42*E44 -> 546.624
B48: Power Cost ($/MWh), Including T&D | E48: 110
B50: Total Annual Power Cost Per Rack | E50: =E46*E48 -> 60128.64
B52: Power Used by ASICs (MW) | E52: =C2/Trainium3!E44 -> 769.23077
B53: Number of ASICs Required | E53: =((E52*1000)/E38*E7) -> 769230.77
B54: Number of Racks | E54: =E53/E7 -> 12019.231
B56: Total Cost of the ASICs ($M) | E56: =E17*E54 -> 4430.7692
B57: Total Cost of ASIC/Racks ($M) | E57: =E54*E36 -> 9587.7404
B58: Annual Power Costs ($M) | E58: =E54*E50/1000000 -> 722.7
B60: Annual Power Costs as % of ASIC Cost | E60: =E58/E56 -> 0.16310938
B62: 2. Powered Shell, Mechanical, Electrical, Labor, Materials
...

Sheet TPUv7
B2: Size Data Center (MW) | C2: 1000 | F2: 10
F3: 1000
B5: 1. IT Hardware
B7: TPUs Per Rack | E7: ='[17]TPUv7 Rack Cost Template'!D8 -> 64
B9: Cost Per TPU | E9: ='[17]TPUv7 Rack Cost Template'!C8 -> 15840
B11: HBM Contribution | E11: =(E15*E14) -> 4224
B12: HBM % of TPU Costs | E12: =E11/E9 -> 0.26666667
B13: Memory % of GW Scale Capex | E13: =((E11/1000000*E54)+(E23*E55))/E64 -> 352.86388
B14: HBM3e GB per TPUv7 chip | E14: 192
B15: Implied Price per GB of HBM3E | E15: 22
B17: TPU Cost Per Rack ($M) | E17: =(E7*E9)/1000000 -> 1.01376
B18: % of Rack Cost | E18: =E17/E37 -> 0.70566097
B20: Other Rack Costs | E20: =E37-E17 -> 0.42285056
B21: % of Rack Cost | E21: =E20/E37 -> 0.29433903
B23: Memory Contribution (Rack Level) | E23: =(E26*E25)/1000000 -> 0.090112
B24: % of TPU Costs | E24: =E23/E17 -> 0.088888889
B25: GB DDR5 / Rack | E25: =E7*192 -> 12288
B26: Price Per GB DDR5 | E26: 7.3333333
B27: Memory as a % of GW-Scale Capex | E27: =E23+('[17]TPUv7 Rack Cost Template'!C23*'[17]TPUv7 Rack Cost Template'!C24*(1+'[17]TPUv7 Rack Cost Template'!C25))/1000000 -> 0.096448
B29: CPU Contribution | E29: =(E32*E31)/1000000 -> 0.11984896
B30: % of TPU Costs | E30: =E29/E17 -> 0.11822222
B31: CPUs / Rack | E31: =E7/2 -> 32
B32: Implied Price per CPU | E32: 3745.28
B34: Other Contribution | E34: =E35*E17 -> 0.2128896
B35: % of TPU Costs | E35: 0.21
B37: Total Rack Cost ($M) | E37: =E17+E23+E29+E34 -> 1.4366106
B39: Power Required Per Rack (kW) | E39: =10000/144 -> 69.444444
B41: Utilization Rate | E41: 0.75
B43: Annual Power Per Rack (MWh) | E43: =E39*8.76*E41 -> 456.25
B45: Power Usage Effectiveness (PUE) | E45: 1.3
B47: Total Power Per Rack (MWh) | E47: =E43*E45 -> 593.125
B49: Power Cost ($/MWh), Including T&D | E49: 110
B51: Total Annual Power Cost Per Rack | E51: =E47*E49 -> 65243.75
B53: Power Used by TPUs (MW) | E53: =C2/TPUv7!E45 -> 769.23077
B54: Number of TPUs Required | E54: =((E53*1000)/E39*E7) -> 708923.08
B55: Number of Racks | E55: =E54/E7 -> 11076.923
B57: Total Cost of the TPUs ($M) | E57: =E17*E55 -> 11229.342
B58: Total Cost of TPU/Racks ($M) | E58: =E55*E37 -> 15913.225
B59: Annual Power Costs ($M) | E59: =E55*E51/1000000 -> 722.7
B61: Annual Power Costs as % of TPU Cost | E61: =E59/E57 -> 0.064358181
...

Sheet Trainium Rack Cost (64)
C4: Trainium 3 | D4: ASP | E4: # | F4: Value (US$) | G4: % of BOM
C5: Compute Trays (PCB) | D5: 2400 | E5: 32 | F5: =E5*D5 -> 76800 | G5: =F5/$F$21 -> 0.096276796
C6: Switch Board (PCB) | D6: 2000 | E6: 8 | F6: =E6*D6 -> 16000 | G6: =F6/$F$21 -> 0.020057666
C7: Peripheral Boards | D7: 600 | E7: 32 | F7: =E7*D7 -> 19200 | G7: =F7/$F$21 -> 0.024069199
C8: Trainium 3 Chip | D8: =D28 -> 5760 | E8: 64 | F8: =E8*D8 -> 368640 | G8: =F8/$F$21 -> 0.46212862
C9: EFA NIC Assembly | D9: 1200 | E9: 32 | F9: =E9*D9 -> 38400 | G9: =F9/$F$21 -> 0.048138398
C10: AEC/DAC Copper Cables | D10: 20 | E10: 2000 | F10: =E10*D10 -> 40000 | G10: =F10/$F$21 -> 0.050144164
C11: CPU DDR5 | D11: 10 | E11: =128*E15 -> 4096 | F11: =E11*D11 -> 40960 | G11: =F11/$F$21 -> 0.051347624
C12: PCIe Retimers | D12: 300 | E12: =4*E6 -> 32 | F12: =E12*D12 -> 9600 | G12: =F12/$F$21 -> 0.012034599
C13: PSU, BSUs, Busbar Distributino | F13: 75000 | G13: =F13/$F$21 -> 0.094020308
C14: NeuronSwitch ASIC | D14: 3500 | E14: 8 | F14: =E14*D14 -> 28000 | G14: =F14/$F$21 -> 0.035100915
C15: Graviton 4 CPU | D15: 2000 | E15: =E5 -> 32 | F15: =E15*D15 -> 64000 | G15: =F15/$F$21 -> 0.080230663
C16: Backplane | D16: 10000 | E16: 1 | F16: =E16*D16 -> 10000 | G16: =F16/$F$21 -> 0.012536041
C17: Thermal Components
C18: Cooling fans (8x per compute tray) | D18: 25 | E18: =8*E5 -> 256 | F18: =E18*D18 -> 6400
C19: Cooling fans (6x per switch tray) | D19: 25 | E19: =6*E6 -> 48 | F19: =E19*D19 -> 1200
C20: Others | D20: 3500 | E20: 1 | F20: =E20*D20 -> 3500
C21: Total | F21: =SUM(F5:F20) -> 797700
C23: Chip Costs
C24: HBM3e Cost per GB | D24: 20
C25: (X) GB per Trainium Chips | D25: 144
C26: (=) Memory Cost per Chip | D26: =D24*D25 -> 2880
C27: (/) % of Chip Cost in Memory | D27: 0.5
C28: (=) Chip Cost to AMZN | D28: =D26/D27 -> 5760

Sheet TPUv7 Rack Cost Template
B4: Ironwood TPU7 Rack | C4: ASP | D4: # | E4: Value (US$) | F4: % of BOM
B5: Ironwood Compute Tray | C5: ='[17]GB200 Rack Cost_for ASIC'!D5*1.25 -> 3500 | D5: 16 | E5: =D5*C5 -> 56000 | F5: =E5/$E$17 -> 0.039263094
B6: Optical Transceivers | C6: =[18]Master!$F$97 -> 819.9562 | D6: 96 | E6: =D6*C6 -> 78715.795 | F6: =E6/$E$17 -> 0.055189743
B7: Peripheral Boards | C7: ='[17]GB200 Rack Cost_for ASIC'!D7 -> 600 | D7: =D5+1 -> 17 | E7: =D7*C7 -> 10200 | F7: =E7/$E$17 -> 0.007151492
B8: TPUv7 | C8: =C26 -> 15840 | D8: 64 | E8: =D8*C8 -> 1013760 | F8: =E8/$E$17 -> 0.71077417
B9: Axion CPU | C9: ='[17]GB200 Rack Cost_for ASIC'!D10*0.75 -> 3750 | D9: =64/4 -> 16 | E9: =D9*C9 -> 60000 | F9: =E9/$E$17 -> 0.0420676
B10: CPU Trays | C10: 800 | D10: =D9 -> 16 | E10: =D10*C10 -> 12800 | F10: =E10/$E$17 -> 0.0089744214
B11: PSUs, BSUs | E11: 100000 | F11: =E11/$E$17 -> 0.070112667
B12: Thermal Components | F12: =E12/$E$17 -> 0
B13: Cold Plate Module (8x per compute tray) | C13: ='[17]GB200 Rack Cost_for ASIC'!D12*1.25 -> 375 | D13: =D5*8 -> 128 | E13: =D13*C13 -> 48000 | F13: =E13/$E$17 -> 0.03365408
B14: Cooling fans | C14: ='[17]GB200 Rack Cost_for ASIC'!D14*3 -> 75 | D14: 24 | E14: =D14*C14 -> 1800 | F14: =E14/$E$17 -> 0.001262028
B15: Side car CDU (supports 6x racks) | C15: 120000 | D15: =1/6 -> 0.16666667 | E15: =D15*C15 -> 20000 | F15: =E15/$E$17 -> 0.014022533
B16: Manifold CDM | C16: 25000 | D16: 1 | E16: =D16*C16 -> 25000 | F16: =E16/$E$17 -> 0.017528167
B17: Total | E17: =SUM(E5:E16) -> 1426275.8
B19: Chip Costs
B20: HBM3e Cost per GB | C20: 22
B21: (X) GB per TPUv7 Chips | C21: 192
B22: (=) Memory Cost per Chip | C22: =C20*C21 -> 4224
B23: (/) % of Chip Cost in Memory | C23: 0.4
B24: (=) Total Chip Manufacturing Cost | C24: =C22/C23 -> 10560
B25: (X) Implied Gross Margin | C25: 0.5
B26: (=) Chip Cost to GOOGL | C26: =C24*(1+C25) -> 15840

Sheet Vera Rubin
B2: Size Data Center (MW) | C2: 1000 | G2: 10
B3: Square Foot / 100 MW | C3: 333333.33 | G3: 100
G4: 1000
B6: 1. IT Hardware
B8: GPUs Per Rack | E8: 72
B10: Cost Per GPU | E10: ='VR200 BoM '!K6 -> 60000
B12: HBM Contribution | E12: =(E15*E16) -> 4025
B13: HBM % of GPU Costs | E13: =E12/E10 -> 0.067083333
B14: Memory % of GW Scale Capex | E14: =((E12/1000000*E52)+(E24*E53))/E67 -> 0.20816607
B15: HBM4 GB per Vera Rubin chip | E15: =20700/72 -> 287.5
B16: Implied Price per GB of HBM4E | E16: 14
B18: GPU Cost Per Rack ($M) | E18: ='VR200 BoM '!C33/1000000 -> 4.32
B19: % of Rack Cost | E19: =E18/E35 -> 0.51187092
B21: Other Rack Costs | E21: =E35-E18 -> 4.1196277
B22: % of Rack Cost | E22: =E21/E35 -> 0.48812908
B24: Memory Contribution (Rack Level) | E24: ='VR200 BoM '!U30/1000000 -> 2.27808
B25: % of GPU Costs | E25: =E24/E18 -> 0.52733333
B27: CPU Contribution | E27: ='[17]VR200 BoM '!C34/1000000 -> 0.198
B28: % of GPU Costs | E28: =E27/E18 -> 0.045833333
B29: CPUs / Rack | E29: =E8/2 -> 36
B30: Implied Price per CPU | E30: =E27/E29*1000000 -> 5500
B32: Other Contribution | E32: =E35-E27-E24-E18 -> 1.6435477
B33: % of GPU Costs | E33: =E32/E18 -> 0.38045085
B35: Total Rack Cost ($M) | E35: ='VR200 BoM '!C45/1000000 -> 8.4396277
B37: Power Required Per Rack (kW) | E37: 185
B39: Utilization Rate | E39: 0.75
B41: Annual Power Per Rack (MWh) | E41: =E37*8.76*E39 -> 1215.45
B43: Power Usage Effectiveness (PUE) | E43: 1.3
B45: Total Power Per Rack (MWh) | E45: =E41*E43 -> 1580.085
B47: Power Cost ($/MWh), Including T&D | E47: 110
B49: Total Annual Power Cost Per Rack | E49: =E45*E47 -> 173809.35
B51: Power Used by GPUs (MW) | E51: =C2/'Vera Rubin'!E43 -> 769.23077
B52: Number of GPUs Required | E52: =((E51*1000)/E37*E8) -> 299376.3
B53: Number of Racks | E53: =E52/E8 -> 4158.0042
B55: Total Cost of the GPUs ($M) | E55: =E18*E53 -> 17962.578
B56: Total Cost of GPU/Racks ($M) | E56: =E53*E35 -> 35092.007
B57: Annual Power Costs ($M) | E57: =E53*E49/1000000 -> 722.7
B59: Annual Power Costs as % of GPU Cost | E59: =E57/E55 -> 0.040233646
B61: 2. Powered Shell, Mechanical, Electrical, Labor, Materials
B62: Cost per MW ($M) | E62: ='[17]Outside Rack Cost Backup'!$C$4 -> 16.2
...

Sheet GB300 
B2: Size Data Center (MW) | C2: 1000 | F2: 10
B3: Square Foot / 100 MW | C3: 333333.33 | F3: 100
F4: 1000
B6: 1. IT Hardware
B8: GPUs Per Rack | E8: 72
B10: Cost Per GPU | E10: 40000
B12: HBM Contribution | E12: =(E16*E15) -> 4500
B13: HBM % of GPU Costs | E13: =E12/E10 -> 0.1125
B14: Memory % of GW Scale Capex | E14: =((E12/1000000*E52)+(E24*E53))/E67 -> 0.17565395
B15: HBM3e GB per Vera Rubin chip | E15: 279
B16: Implied Price per GB of HBM4E | E16: 16.129032
B18: GPU Cost Per Rack ($M) | E18: =(E8*E10)/1000000 -> 2.88
B19: % of Rack Cost | E19: =E18/E35 -> 0.62227876
B21: Other Rack Costs | E21: =E35-E18 -> 1.7481509
B22: % of Rack Cost | E22: =E21/E35 -> 0.37772124
B24: Memory Contribution (DDR5) | E24: ='[17]GB300 BoM'!U30/1000000 -> 0.9499392
B25: % of GPU Costs | E25: =E24/E18 -> 0.32984
B27: CPU Contribution | E27: ='[17]GB300 BoM'!C33/1000000 -> 0.18
B28: % of GPU Costs | E28: =E27/E18 -> 0.0625
B29: CPUs / Rack | E29: =E8/2 -> 36
B30: Estimated Price per CPU | E30: =E27/E29*1000000 -> 5000
B32: Other Contribution | E32: =E35-E27-E24-E18 -> 0.61821167
B33: % of GPU Costs | E33: =E32/E18 -> 0.21465683
E34: =E35/E8 -> 0.064279873
B35: Total Rack Cost ($M) | E35: ='GB300 BoM'!C43/1000000 -> 4.6281509
B37: Power Required Per Rack (kW) | E37: 135
B39: Utilization Rate | E39: 0.75
B41: Annual Power Per Rack (MWh) | E41: =E37*8.76*E39 -> 886.95
B43: Power Usage Effectiveness (PUE) | E43: 1.2
B45: Total Power Per Rack (MWh) | E45: =E41*E43 -> 1064.34
B47: Power Cost ($/MWh), Including T&D | E47: 110
B49: Total Annual Power Cost Per Rack | E49: =E45*E47 -> 117077.4
B51: Power Used by GPUs (MW) | E51: =C2/'GB300 '!E43 -> 833.33333
B52: Number of GPUs Required | E52: =((E51*1000)/E37*E8) -> 444444.44
B53: Number of Racks | E53: =E52/E8 -> 6172.8395
B55: Total Cost of the GPUs ($M) | E55: =E18*E53 -> 17777.778
B56: Total Cost of GPU/Racks ($M) | E56: =E53*E35 -> 28568.833
B57: Annual Power Costs ($M) | E57: =E53*E49/1000000 -> 722.7
B59: Annual Power Costs as % of GPU Cost | E59: =E57/E55 -> 0.040651875
B61: 2. Powered Shell, Mechanical, Electrical, Labor, Materials
...

Sheet VR200 BoM 
B2: VR200 NVL72
B3: VR200 NVL72 Bill of materials (US$) | E3: Compute Tray | F3: =SUM(F4:F17) -> 442588 | P3: # of BMC
B4: 18x Compute Tray | C4: =+F3*18 -> 7966584 | E4: Compute board (2x) | F4: =+I4*2 -> 378399.33 | H4: Compute board | I4: =+SUM(I5:I11) -> 189199.67 | O4: NVL36 | P4: 41
B5: 9x Switch Tray | C5: =+F19*9 -> 239277 | E5: BF4 DPU Module | F5: 10000 | H5: Vera (1x) | I5: 5500 | K5: R200 ASP | O5: NVL72 | P5: 85 | S5: 1x Cable Cartridge | T5: ASP (US$) | U5: Total (US$)
B6: Rack Chassis | C6: 3000 | E6: CX9 NIC | F6: =5500*4 -> 22000 | H6: R200 (2x) | I6: =+K6*2 -> 120000 | K6: 60000 | S6: 36x NVLink Male | T6: 25 | U6: =+T6*36 -> 900
B7: Manifold (CDM) | C7: 13500 | E7: Storage | F7: =+T29+(T28*4) -> 23072 | H7: Cold Plate (2x) | I7: =400 -> 400 | O7: GB300 | P7: 71 | S7: Cables | T7: 1250 | U7: =+T7*1 -> 1250
B8: Power supply | C8: 76000 | E8: Midplane PCB | F8: 2000 | H8: PCB (HDI) | I8: =1400/(1-70%) -> 4666.6667 | O8: VR200 | P8: 80 | S8: Spine chassis | T8: 150 | U8: =+T8*1 -> 150
B9: Management switch | C9: =2000*2 -> 4000 | E9: Paladin connectors | F9: =+V35 -> 2066.6667 | H9: SOCAMM (8x per board) | I9: =(T26*8)/(1-70%) -> 51200 | S9: Total | U9: =SUM(U6:U8) -> 2300
B10: Other cooling | C10: 800 | E10: NVQD (20x) | F10: =20*20 -> 400 | H10: Assembly/Test | I10: =450/(1-70%) -> 1500 | S10: Nvidia margin | U10: 0.7
B11: 4x Cable Cartridge | C11: =+U12 -> 30666.667 | E11: Inner Manifold | F11: 1000 | H11: Others | I11: =5000+933 -> 5933 | S11: ASP in BOM | U11: =+U9/(1-U10) -> 7666.6667
B12: Others | C12: 77000 | E12: Cold Plate (3x) | F12: =150*3 -> 450 | S12: 4x Cable Cartridge | U12: =+U11*4 -> 30666.667
B13: Rack assembly & test | C13: 28800 | E13: Floating mount | F13: =50*2 -> 100
B14: Total | C14: =+SUM(C4:C13) -> 8439627.7 | E14: Chassis | F14: 250
E15: Railkit | F15: 50
B16: =+B3 -> VR200 NVL72 Bill of materials (US$) | E16: Assembly/Test | F16: 1800
B17: =+B4 -> 18x Compute Tray | C17: =+C4/C$14 -> 0.9439497 | E17: Others | F17: 1000
B18: =+B5 -> 9x Switch Tray | C18: =+C5/C$14 -> 0.028351606
B19: =+B6 -> Rack Chassis | C19: =+C6/C$14 -> 0.00035546592 | E19: Switch Tray | F19: =SUM(F20:F27) -> 26586.333
B20: =+B7 -> Manifold (CDM) | C20: =+C7/C$14 -> 0.0015995966 | E20: Switch board | F20: =+I20 -> 23066.333 | H20: Switch board | I20: =+SUM(I21:I25) -> 23066.333
B21: =+B8 -> Power supply | C21: =+C8/C$14 -> 0.0090051366 | E21: Chassis | F21: 250 | H21: NVLink switch chip (4x) | I21: =+K23*4 -> 16000
B22: =+B9 -> Management switch | C22: =+C9/C$14 -> 0.00047395456 | E22: Floating mount & others | F22: =50*2+60 -> 160 | H22: PCB (MLB) | I22: =1450/(1-70%) -> 4833.3333 | K22: NVLink switch chip ASP
B23: =+B10 -> Other cooling | C23: =+C10/C$14 -> 9.4790912e-05 | E23: NVQD (18x) | F23: =20*18 -> 360 | H23: Cold Plate (2x) | I23: =200*2 -> 400 | K23: 4000
B24: =+B11 -> 4x Cable Cartridge | C24: =+C11/C$14 -> 0.0036336516 | E24: Railkit | F24: 50 | H24: Assembly/Test | I24: 350
B25: =+B12 -> Others | C25: =+C12/C$14 -> 0.0091236252 | E25: Paladin connectors | F25: =+V42 -> 533.33333 | H25: Others | I25: =550+933 -> 1483 | S25: Memory (ex-HBM) | T25: ASP (US$) | U25: Total (US$)
B26: =+B13 -> Rack assembly & test | C26: =+C13/C$14 -> 0.0034124728 | E26: Assembly/Test | F26: =350/(1-70%) -> 1166.6667 | S26: 288x 192GB SOCAMM | T26: =96*20 -> 1920 | U26: =+T26*288/(1-70%) -> 1843200
B27: =+B14 -> Total | C27: =+SUM(C17:C26) -> 1 | E27: Others | F27: 1000 | S27: LPDDR5X 128GB (BF4) | T27: =128*8*1.0625 -> 1088 | U27: =+T27*18 -> 19584
S28: E1.S NVMe SSD (16TB) | T28: =350*16 -> 5600 | U28: =+T28*72 -> 403200
E29: Peripheral PCB boards | F29: =+F30*18+F31*72+F32*36 -> 25830 | H29: ABF Substrate Content per Rack | I29: =SUM(I30:I34) -> 20340 | K29: MLCC Content per Rack | L29: =SUM(L30:L34) -> 4320 | S29: M.2 SSD (1.92TB) | T29: =350*1.92 -> 672 | U29: =+T29*18 -> 12096
E30: BF4-Module (18x, 1x per compute tray) | F30: 255 | H30: R200 ($200 each, 72x per rack) | I30: =200*72 -> 14400 | K30: Strata ($90 per board, 36x boards) | L30: =90*36 -> 3240 | S30: Total | U30: =SUM(U26:U29) -> 2278080
E31: CX9-Orchid Module (72x, 4x per compute tray) | F31: 270 | H31: Vera ($60 each, 36x per rack) | I31: =60*36 -> 2160 | K31: Switch board ($45 per board, 9x boards) | L31: =45*9 -> 405
B32: Simplied VR200 NVL72 BOM | E32: Other peripheral boards (45x) | F32: 50 | H32: NVLink ($30 each, 36x per rack) | I32: =30*36 -> 1080 | K32: BlueField Module ($5 per board, 18x boards) | L32: =5*18 -> 90
B33: Rubin GPU | C33: =+K6*72 -> 4320000 | H33: BlueField ($30 each, 18x per rack) | I33: =30*18 -> 540 | K33: CX9 Orchid Module ($5 per board, 72x boards) | L33: =5*72 -> 360
B34: Vera CPU | C34: =+I5*36 -> 198000 | H34: CX ($30 each, 72x per rack) | I34: =30*72 -> 2160 | K34: Peripheral boards ($5 per board, 45x boards) | L34: =5*45 -> 225 | S34: Paladin connectors | T34: Quantity | U34: ASP (US$) | V34: Total (US$)
B35: Networking chips | C35: =(4*9*K23)+((F5-700)*18)+((F6-700)*18) -> 694800 | S35: Compute tray | T35: =SUM(T36:T41) -> 28 | U35: =+V35/T35 -> 73.809524 | V35: =SUM(V36:V41) -> 2066.6667
B36: Memory | C36: =+(I9*2+F7)*18+(T27*18) -> 2278080 | S36: 4x NVLink Female | T36: 4 | U36: 20 | V36: =+(U36*T36)/(1-70%) -> 266.66667
B37: PCB | C37: =+(I8*0.3*36)+(F8*0.75*18)+(F30*18)+(F31*72)+(I22*0.3*9)+(F32*45) -> 116730 | S37: 6x Board2Board Female (Compute board) | T37: 6 | U37: 20 | V37: =+(U37*T37)/(1-70%) -> 400
B38: ABF Substrate | C38: =+I29 -> 20340 | S38: 1x Board2Board Female (BF4) | T38: 1 | U38: 20 | V38: =+(U38*T38)/(1-70%) -> 66.666667
B39: MLCC | C39: =+L29 -> 4320 | S39: 4x Board2Board Female (CX9) | T39: 4 | U39: 20 | V39: =+(U39*T39)/(1-70%) -> 266.66667
B40: Cooling | C40: =+((F10+F11+F12+F13)*18)+(I7*36)+(I23*9)+((F22+F23)*9)+C7+C10 -> 72080 | S40: 1x Board2Board Female | T40: 1 | U40: 20 | V40: =+(U40*T40)/(1-70%) -> 66.666667
B41: Power supply | C41: =+C8 -> 76000 | S41: 12x Board2Board Male (Midplane) | T41: 12 | U41: 25 | V41: =+(U41*T41)/(1-70%) -> 1000
...

Sheet Memory sensitivity
B2: Current NVL cost with 96GB | D2: ='VR200 BoM '!C14 -> 8439627.7
B3: Assumed SOCAMM cost | D3: 8
B4: Assumed HBM cost | D4: 13.8
B6: Required margin pass through | D6: 0.7
B8: SOCAMM cost increase | D8: 8
B9: SOCAMM per compute board | D9: =96*8 -> 768
B10: Number of compute boards | D10: 36
D11: =D9*D10 -> 27648
B12: NVL increase | D12: =(D11*D8)/(1-D6) -> 737280
B13: % increase | D13: =D12/D2 -> 0.087359304
B15: HBM cost increase | D15: 8
B16: HBM per compute board | D16: =72*288 -> 20736
B17: NVL increase | D17: =(D16*D15)/(1-D6) -> 552960
B18: % increase | D18: =D17/D2 -> 0.065519478
B20: Total increase | D20: =(D17+D12) -> 1290240
B21: % increase | D21: =D20/D2 -> 0.15287878
B28: Current NVL cost with 192GB | D28: 7710987.7
B29: Assumed SOCAMM cost | D29: 8
B30: Assumed HBM cost | D30: 13.8
B32: Required margin pass through | D32: 0.7
B34: SOCAMM cost increase | D34: 15
B35: SOCAMM per compute board | D35: =192*8 -> 1536
B36: Number of compute boards | D36: 36
D37: =D35*D36 -> 55296
B38: NVL increase | D38: =(D37*D34)/(1-D32) -> 2764800
B39: % increase | D39: =D38/D28 -> 0.35855329
B41: HBM cost increase | D41: 8
B42: HBM per compute board | D42: =72*288 -> 20736
B43: NVL increase | D43: =(D42*D41)/(1-D32) -> 552960
B44: % increase | D44: =D43/D28 -> 0.071710658
B46: Total increase | D46: =(D43+D38) -> 3317760
B47: % increase | D47: =D46/D28 -> 0.43026395

Sheet GB300 BoM
B2: GB300 NVL72
B3: GB300 NVL72 Bill of materials (US$) | E3: Compute Tray | F3: =SUM(F4:F16) -> 240331.07 | P3: # of BMC
B4: 18x Compute Tray | C4: =+F3*18 -> 4325959.2 | E4: Compute board (2x) | F4: =+I4*2 -> 217273.33 | H4: Compute board | I4: =+SUM(I5:I11) -> 108636.67 | O4: NVL36 | P4: 41
B5: 9x Switch Tray | C5: =+F18*9 -> 131025 | E5: BF3 DPU Module | F5: 5500 | H5: Grace (1x) | I5: 5000 | K5: B300 ASP | O5: NVL72 | P5: 85 | S5: 1x Cable Cartridge | T5: ASP (US$) | U5: Total (US$)
B6: Rack Chassis | C6: 3000 | E6: CX8 NIC | F6: =4500*2 -> 9000 | H6: B300 (2x) | I6: =+K6*2 -> 70000 | K6: =35000 -> 35000 | S6: 36x NVLink Male | T6: 30 | U6: =+T6*36 -> 1080
B7: Manifold (CDM) | C7: 13500 | E7: Storage | F7: =+T29+(T28*4) -> 4614.4 | H7: Cold Plate (3x) | I7: =250*3 -> 750 | O7: GB300 | P7: 71 | S7: Cables | T7: 1250 | U7: =+T7*1 -> 1250
B8: Power supply | C8: 57600 | E8: Paladin connectors | F8: =+V35 -> 333.33333 | H8: PCB (HDI) | I8: =650/0.3 -> 2166.6667 | O8: VR200 | P8: 80 | S8: Spine chassis | T8: 150 | U8: =+T8*1 -> 150
B9: Management switch | C9: =1650*2 -> 3300 | E9: NVQD (8x) | F9: =25*8 -> 200 | H9: LPDDR5X (480GB) | I9: =+T26/(1-70%) -> 25600 | S9: Total | U9: =SUM(U6:U8) -> 2480
B10: Other cooling | C10: 800 | E10: Inner Manifold | F10: 300 | H10: Assembly/Test | I10: 1120 | S10: Nvidia margin | U10: 0.7
B11: 4x Cable Cartridge | C11: =+U12 -> 33066.667 | E11: Fans (8x) | F11: =20*8 -> 160 | H11: Others | I11: 4000 | S11: ASP in BOM | U11: =+U9/(1-U10) -> 8266.6667
B12: Others | C12: 37500 | E12: Floating mount | F12: =50*2 -> 100 | S12: 4x Cable Cartridge | U12: =+U11*4 -> 33066.667
B13: Rack assembly & test | C13: 22400 | E13: Chassis | F13: 200
B14: Total | C14: =+SUM(C4:C13) -> 4628150.9 | E14: Railkit | F14: 50
E15: Assembly/Test | F15: 1600
B16: =+B3 -> GB300 NVL72 Bill of materials (US$) | E16: Others | F16: 1000
B17: =+B4 -> 18x Compute Tray | C17: =+C4/C$14 -> 0.93470574
B18: =+B5 -> 9x Switch Tray | C18: =+C5/C$14 -> 0.028310443 | E18: Switch Tray | F18: =SUM(F19:F26) -> 14558.333
B19: =+B6 -> Rack Chassis | C19: =+C6/C$14 -> 0.00064820705 | E19: Switch board | F19: =+I19 -> 11971.667 | H19: Switch board | I19: =+SUM(I20:I24) -> 11971.667
B20: =+B7 -> Manifold (CDM) | C20: =+C7/C$14 -> 0.0029169317 | E20: Chassis | F20: 200 | H20: NVLink switch chip (2x) | I20: =+K21*2 -> 7200 | K20: NVLink switch chip ASP
B21: =+B8 -> Power supply | C21: =+C8/C$14 -> 0.012445575 | E21: Other cooling (includes 6x fans, etc) | F21: =150+60 -> 210 | H21: PCB (MLB) | I21: =800/(1-70%) -> 2666.6667 | K21: 3600
B22: =+B9 -> Management switch | C22: =+C9/C$14 -> 0.00071302775 | E22: Floating mount | F22: =50*2 -> 100 | H22: Cold Plate (2x) | I22: =200*2 -> 400
B23: =+B10 -> Other cooling | C23: =+C10/C$14 -> 0.00017285521 | E23: NVQD | F23: =20*18 -> 360 | H23: Assembly/Test | I23: 275
B24: =+B11 -> 4x Cable Cartridge | C24: =+C11/C$14 -> 0.0071446821 | E24: Railkit | F24: 50 | H24: Others | I24: =500+930 -> 1430
B25: =+B12 -> Others | C25: =+C12/C$14 -> 0.0081025881 | E25: Paladin connectors | F25: =+V38 -> 666.66667 | S25: Memory (ex-HBM) | T25: ASP (US$) | U25: Total (US$)
B26: =+B13 -> Rack assembly & test | C26: =+C13/C$14 -> 0.0048399459 | E26: Assembly/Test | F26: =300/(1-70%) -> 1000 | S26: 36x 480GB LPDDR5X | T26: =16*480 -> 7680 | U26: =+T26*36/(1-70%) -> 921600
B27: =+B14 -> Total | C27: =+SUM(C17:C26) -> 1 | E27: Others | F27: 600 | S27: LPDDR5X 32GB (BF3) | T27: =5*32 -> 160 | U27: =+T27*18 -> 2880
S28: E1.S NVMe SSD (7.68TB) | T28: =70*16 -> 1120 | U28: =+T28*72 -> 80640
E29: Peripheral PCB boards (90x) | F29: =+F30*90 -> 4500 | H29: ABF Substrate Content per Rack | I29: =SUM(I30:I34) -> 11160 | K29: MLCC Content per Rack | L29: =SUM(L30:L32) -> 1530 | S29: M.2 SSD (1.92TB) | T29: =70*1.92 -> 134.4 | U29: =+T29*18 -> 2419.2
E30: PCB board only ASP (US$) | F30: 50 | H30: B200 ($100 each, 72x per rack) | I30: =100*72 -> 7200 | K30: Bianca ($25 per board, 36x boards) | L30: =25*36 -> 900 | S30: Total | U30: =SUM(U26:U29) -> 1007539.2
B31: Simplied GB200 NVL72 BOM | H31: Grace ($50 each, 36x per rack) | I31: =50*36 -> 1800 | K31: Switch board ($20 per board, 9x boards) | L31: =20*9 -> 180
B32: Blackwell GPU | C32: =+K6*72 -> 2520000 | H32: NVLink ($30 each, 18x per rack) | I32: =30*18 -> 540 | K32: Peripheral boards ($5 per board, 90x boards) | L32: =5*90 -> 450
B33: Grace CPU | C33: =+I5*36 -> 180000 | H33: BlueField ($30 each, 18x per rack) | I33: =30*18 -> 540
B34: NVLink Switch chip | C34: =+K21*2*9 -> 64800 | H34: CX ($30 each, 36x per rack) | I34: =30*36 -> 1080 | S34: Paladin connectors | T34: Quantity | U34: ASP (US$) | V34: Total (US$)
B35: Memory | C35: =+(I9*2+F7)*18+(T27*18) -> 1007539.2 | S35: Compute tray | T35: =SUM(T36:T36) -> 4 | U35: =+V35/T35 -> 83.333333 | V35: =SUM(V36:V36) -> 333.33333
B36: PCB | C36: =(+I8*0.3*36)+(I21*0.3*9)+F29 -> 35100 | S36: 4x NVLink Female | T36: 4 | U36: 25 | V36: =+(U36*T36)/(1-70%) -> 333.33333
B37: ABF Substrate | C37: =+I29 -> 11160 | S37: Switch tray | T37: =SUM(T38) -> 8 | U37: =+V37/T37 -> 83.333333 | V37: =SUM(V38) -> 666.66667
B38: MLCC | C38: =+L29 -> 1530 | S38: 8x NVLink Female | T38: 8 | U38: 25 | V38: =+(U38*T38)/(1-70%) -> 666.66667
B39: Cooling | C39: =+((F9+F10+F11+F12)*18)+(I7*36)+(I22*9)+((F21+F22+F23)*9)+C7+C10 -> 64610 | S39: Cartridge | T39: =SUM(T40) -> 36 | U39: =+V39/T39 -> 100 | V39: =SUM(V40) -> 3600
B40: Power supply | C40: =+C8 -> 57600 | S40: 36x NVLink Male | T40: 36 | U40: 30 | V40: =+(U40*T40)/(1-70%) -> 3600
B41: Others | C41: =+C43-C42-SUM(C32:C40) -> 633811.67
...

Sheet TSMC
E1: 2024 | F1: 2025 | G1: 2026 | H1: 2027 | I1: 2028 | J1: 2029 | K1: 2030
B2: Leading edge nodes
C3: 10nm
C4: 7nm
C5: 5nm
C6: 3nm
C7: 2nm
C8: A16
B9: CoWos
C10: Nvidia
C14: Amazon
D15: Trn2 Units | G15: 100 | H15: 140
D16: Trn3 Units
D17: Trn4 Units

Sheet DRAM

Sheet Chip sales
E1: 2024 | F1: 2025 | G1: 2026 | H1: 2027 | I1: 2028 | J1: 2029 | K1: 2030
B2: Nvidia
C3: Amazon
D4: GB300/200 Units | F4: 67680 | G4: 520000 | H4: 187500 | I4: 0
D5: Vera Rubin Units | F5: 0 | G5: 130000 | H5: 421875 | I5: 180000
D6: Rubin Ultra Units | F6: 0 | G6: 0 | H6: 140625 | I6: 420000
D7: B200 Units | F7: 212320 | G7: 0 | H7: 0 | I7: 0
D8: Hopper Units | F8: 70000
D9: Total | F9: =SUM(F4:F8) -> 350000 | G9: =SUM(G4:G8) -> 650000 | H9: =SUM(H4:H8) -> 750000 | I9: =SUM(I4:I8) -> 600000
C10: Google
D11: GB300/200 Units | F11: 128160 | G11: 560000 | H11: 187500 | I11: 0
D12: Vera Rubin Units | F12: 0 | G12: 140000 | H12: 421875 | I12: 180000
D13: Rubin Ultra Units | F13: 0 | G13: 0 | H13: 140625 | I13: 420000
D14: B200 Units | F14: 391840 | G14: 0 | H14: 0 | I14: 0
D15: Hopper Units | F15: 130000 | G15: 0 | H15: 0 | I15: 0
D16: Total | F16: =SUM(F11:F15) -> 650000 | G16: =SUM(G11:G15) -> 700000 | H16: =SUM(H11:H15) -> 750000 | I16: =SUM(I11:I15) -> 600000
C17: Meta
D18: GB300/200 Units | F18: 223200 | G18: 560000 | H18: 187500 | I18: 0
D19: Vera Rubin Units | G19: 140000 | H19: 421875 | I19: 180000
D20: Rubin Ultra Units | H20: 140625 | I20: 420000
D21: B200 Units | F21: 256800
D22: Hopper Units | F22: 120000
D23: Total | F23: =SUM(F18:F22) -> 600000 | G23: =SUM(G18:G22) -> 700000 | H23: =SUM(H18:H22) -> 750000 | I23: =SUM(I18:I22) -> 600000
C25: Microsoft
D26: GB300/200 Units | F26: =Microsoft!F7/2 -> 1151315.8 | G26: =F26 -> 1151315.8 | H26: 0 | I26: 0
D27: Vera Rubin Units
D28: Rubin Ultra Units
D29: B200 Units
D30: Hopper Units
D31: Total | F31: =SUM(F26:F30) -> 1151315.8 | G31: =SUM(G26:G30) -> 1151315.8 | H31: =SUM(H26:H30) -> 0 | I31: =SUM(I26:I30) -> 0
C33: Oracle
D34: GB300/200 Units | G34: =Oracle!F6 -> 888888.89
D35: Vera Rubin Units | H35: =Oracle!G7 -> 598752.6 | I35: =Oracle!H7 -> 748440.75
D36: Rubin Ultra Units
D37: B200 Units
D38: Hopper Units
D39: Total | F39: =SUM(F34:F38) -> 0 | G39: =SUM(G34:G38) -> 888888.89 | H39: =SUM(H34:H38) -> 598752.6 | I39: =SUM(I34:I38) -> 748440.75
C41: Spacex
C49: Others
D50: GB300/200 Units | F50: =F57-F18-F11-F4-F26-F34 -> 1084894.2 | G50: =G57-G18-G11-G4-G26-G34 -> 1240515.3 | H50: =H57-H18-H11-H4-H26-H34 -> 2338220 | I50: =I57-I18-I11-I4-I26-I34 -> 680720 | M50: =410*5 -> 2050
...

Sheet Task schedule
B2: Reading emails
B3: Writing emails
B4: Researching
B5: Essay writing
B6: Slide building
B7: Spreadsheet building
B8: Customer service
B10: Image generation
B11: Video generation

Sheet Chip installed base
E1: 2024 | F1: 2025 | G1: 2026 | H1: 2027 | I1: 2028 | J1: 2029 | K1: 2030

Sheet Power
E1: 2024 | F1: 2025 | G1: 2026 | H1: 2027 | I1: 2028 | J1: 2029 | K1: 2030
B2: NVDA
C3: (/) GB300/200 Chips/Rack
C4: (/) Vera Rubin Chips/Rack
C5: (/) Rubin Ultra Chips/Rack
C6: (/) B200 Chips/Server
C7: (/) Hopper Chips/Server
C8: (=) Implied Blackwell Racks
C9: (=) Implied Vera Rubin Racks
C10: (=) Implied Rubin Ultra Racks
C11: (=) Implied B200 Servers
C12: (=) Implied Hopper Servers
C14: (X) KW/Blackwell Rack
C15: (X) KW/Vera Rubin Rack
... C31: Total GPU GW
B51: Amazon
C52: Trn2 power
C53: Trn3 power
C54: Trn4 power
C55: (X) KW/Trn2 Rack
C56: (X) KW/Trn3 Rack
C57: (X) KW/Trn4 Rack
C58: (=) Total Trn2 Rack Power (GW)
C59: (=) Total Trn3 Rack Power (GW)
C60: (=) Total Trn4 Rack Power (GW)
C61: (X) PUE
C62: (=) Total Trn2 IT Power (GW)
C63: (=) Total Trn3 IT Power (GW)
... C65: (=) Total Trn Power (GW)

Sheet Capex
E1: 2024 | F1: 2025 | G1: 2026 | H1: 2027 | I1: 2028 | J1: 2029 | K1: 2030
B2: Amazon
C3: Tranium
D4: (=) Total Trn2 IT Power (GW)
D5: (=) Total Trn3 IT Power (GW)
D6: (=) Total Trn4 IT Power (GW)
D7: (=) Total Trn Power (GW)
D8: Fully Loaded Cost/GW of Trn2
D9: Fully Loaded Cost/GW of Trn3
D10: Fully Loaded Cost/GW of Trn4
D11: (=) Trainium Capex ($mn)

Sheet Rental rates
B2: Silicon Data | D2: Spot
C3: SDB200RT | D3: 5.65
B7: AWS
B13: Google
B21: MSFT
B27: Coreweave
B34: Nebius

Sheet Token pricing
D1: Spot
B2: Anthropic
B3: Input
C4: Fable 5 | D4: 10
C5: Opus 5
C6: Sonnet 5
C7: Haiku 5
C8: Opus 4.8
C9: Opus 4.7
C10: Opus 4.6
C11: Opus 4.5
C12: Opus 4.1
B14: Output
C15: Fable 5 | D15: 50
C16: Opus 5
C17: Sonnet 5
C18: Haiku 5
C19: Opus 4.8
C20: Opus 4.7
C21: Opus 4.6
C22: Opus 4.5
C23: Opus 4.1
B25: Cache write
C26: Fable 5 | D26: 12.5
C27: Opus 5
C28: Sonnet 5
C29: Haiku 5
C30: Opus 4.8
C31: Opus 4.7
C32: Opus 4.6
C33: Opus 4.5
C34: Opus 4.1
B36: Openweight
B37: Input
C38: Deepseek R1 | D38: 1.35
B47: Output
C48: Deepseek R1 | D48: 5.4

Sheet Token volume
D1: FY24 | E1: FY25 | F1: FY26
B2: Open weight models
B8: Frontier

Sheet Token throughput matrix
A1: TPS | G1: Models
C2: Deepseek R1
B3: GB300/200 Units | C3: 2644
B4: Vera Rubin Units
B5: Rubin Ultra Units
B6: B200 Units
A7: Chips | B7: Trn2 Units
B8: Trn3 Units
B9: Trn4 Units
B10: TPUv6
B11: TPUv7
B12: TPUv8/v9/v10

Sheet Model unit economics
F1: Year 1 | G1: Year 2 | H1: Year 3 | I1: Year 4 | J1: Year 5
B2: Leading edge model
B4: Tokens per second | F4: 500 | G4: 1500 | H4: 3000 | I4: =H4 -> 3000 | J4: =I4 -> 3000 | O4: Are Open Models Catching Up?
B5: Seconds per year | F5: =60*60*8760 -> 31536000 | G5: =60*60*8760 -> 31536000 | H5: =60*60*8760 -> 31536000 | I5: =60*60*8760 -> 31536000 | J5: =60*60*8760 -> 31536000
B6: Tokens per year (millions) | F6: =F4*F5/1000000 -> 15768 | G6: =G4*G5/1000000 -> 47304 | H6: =H4*H5/1000000 -> 94608 | I6: =I4*I5/1000000 -> 94608 | J6: =J4*J5/1000000 -> 94608
B7: Blended token price | F7: 5 | G7: =F7*0.3 -> 1.5 | H7: =G7*0.3 -> 0.45 | I7: =H7 -> 0.45 | J7: =I7 -> 0.45
B8: Utilisation | F8: 0.6 | G8: 0.6 | H8: 0.6 | I8: 0.6 | J8: 0.6
B9: Token revenue per chip | F9: =F6*F7*F8 -> 47304 | G9: =G6*G7*G8 -> 42573.6 | H9: =H6*H7*H8 -> 25544.16 | I9: =I6*I7*I8 -> 25544.16 | J9: =J6*J7*J8 -> 25544.16
B10: Blackwells | F10: ='GB300 '!E52 -> 444444.44 | G10: =F10 -> 444444.44 | H10: =G10 -> 444444.44 | I10: =H10 -> 444444.44 | J10: =I10 -> 444444.44
B11: Annual revneue (bn) | F11: =F9*F10/1000000000 -> 21.024 | G11: =G9*G10/1000000000 -> 18.9216 | H11: =H9*H10/1000000000 -> 11.35296 | I11: =I9*I10/1000000000 -> 11.35296 | J11: =J9*J10/1000000000 -> 11.35296
B13: Lagging edge model
B14: Tokens per second | F14: 1500 | G14: 3000 | H14: =G14 -> 3000 | I14: =H14 -> 3000 | J14: =I14 -> 3000
B15: Seconds per year | F15: =60*60*8760 -> 31536000 | G15: =60*60*8760 -> 31536000 | H15: =60*60*8760 -> 31536000 | I15: =60*60*8760 -> 31536000 | J15: =60*60*8760 -> 31536000
B16: Tokens per year (millions) | F16: =F14*F15/1000000 -> 47304 | G16: =G14*G15/1000000 -> 94608 | H16: =H14*H15/1000000 -> 94608 | I16: =I14*I15/1000000 -> 94608 | J16: =J14*J15/1000000 -> 94608
B17: Blended token price | F17: 1 | G17: =F17*0.45 -> 0.45 | H17: =G17 -> 0.45 | I17: =H17 -> 0.45 | J17: =I17 -> 0.45
B18: Utilisation | F18: 0.6 | G18: 0.6 | H18: 0.6 | I18: 0.6 | J18: 0.6
B19: Token revenue per chip | F19: =F16*F17*F18 -> 28382.4 | G19: =G16*G17*G18 -> 25544.16 | H19: =H16*H17*H18 -> 25544.16 | I19: =I16*I17*I18 -> 25544.16 | J19: =J16*J17*J18 -> 25544.16
B20: Blackwells | F20: =F10 -> 444444.44 | G20: =F20 -> 444444.44 | H20: =G20 -> 444444.44 | I20: =H20 -> 444444.44 | J20: =I20 -> 444444.44
B21: Annual revneue (bn) | F21: =F19*F20/1000000000 -> 12.6144 | G21: =G19*G20/1000000000 -> 11.35296 | H21: =H19*H20/1000000000 -> 11.35296 | I21: =I19*I20/1000000000 -> 11.35296 | J21: =J19*J20/1000000000 -> 11.35296
B23: Openweight model
B24: Tokens per second | F24: 3000 | G24: =F24 -> 3000 | H24: =G24 -> 3000 | I24: =H24 -> 3000 | J24: =I24 -> 3000
B25: Seconds per year | F25: =60*60*8760 -> 31536000 | G25: =60*60*8760 -> 31536000 | H25: =60*60*8760 -> 31536000 | I25: =60*60*8760 -> 31536000 | J25: =60*60*8760 -> 31536000
B26: Tokens per year (millions) | F26: =F24*F25/1000000 -> 94608 | G26: =G24*G25/1000000 -> 94608 | H26: =H24*H25/1000000 -> 94608 | I26: =I24*I25/1000000 -> 94608 | J26: =J24*J25/1000000 -> 94608
B27: Blended token price | F27: 0.45 | G27: =F27 -> 0.45 | H27: =G27 -> 0.45 | I27: =H27 -> 0.45 | J27: =I27 -> 0.45
B28: Utilisation | F28: 0.6 | G28: 0.6 | H28: 0.6 | I28: 0.6 | J28: 0.6
B29: Token revenue per chip | F29: =F26*F27*F28 -> 25544.16 | G29: =G26*G27*G28 -> 25544.16 | H29: =H26*H27*H28 -> 25544.16 | I29: =I26*I27*I28 -> 25544.16 | J29: =J26*J27*J28 -> 25544.16
B30: Blackwells | F30: =F20 -> 444444.44 | G30: =F30 -> 444444.44 | H30: =G30 -> 444444.44 | I30: =H30 -> 444444.44 | J30: =I30 -> 444444.44
B31: Annual revneue (bn) | F31: =F29*F30/1000000000 -> 11.35296 | G31: =G29*G30/1000000000 -> 11.35296 | H31: =H29*H30/1000000000 -> 11.35296 | I31: =I29*I30/1000000000 -> 11.35296 | J31: =J29*J30/1000000000 -> 11.35296
B33: Example token split
B34: Leading edge model | F34: 0.2 | G34: 0.2 | H34: 0.2 | I34: 0.2 | J34: 0.2
B35: Lagging edge model | F35: 0.1 | G35: 0.1 | H35: 0.1 | I35: 0.1 | J35: 0.1
B36: Openweight model | F36: 0.7 | G36: 0.7 | H36: 0.7 | I36: 0.7 | J36: 0.7
B38: Token dummy | F38: 1000 | G38: 1000 | H38: 1000 | I38: 1000 | J38: 1000
B40: Leading edge model | F40: =F34*F$38 -> 200 | G40: =G34*G$38 -> 200 | H40: =H34*H$38 -> 200 | I40: =I34*I$38 -> 200 | J40: =J34*J$38 -> 200
B41: Lagging edge model | F41: =F35*F$38 -> 100 | G41: =G35*G$38 -> 100 | H41: =H35*H$38 -> 100 | I41: =I35*I$38 -> 100 | J41: =J35*J$38 -> 100
B42: Openweight model | F42: =F36*F$38 -> 700 | G42: =G36*G$38 -> 700 | H42: =H36*H$38 -> 700 | I42: =I36*I$38 -> 700 | J42: =J36*J$38 -> 700
B44: Revenue multiplier
B45: Leading edge model | F45: =F7/F27 -> 11.111111 | G45: =G7/G27 -> 3.3333333 | H45: =H7/H27 -> 1 | I45: =I7/I27 -> 1 | J45: =J7/J27 -> 1
B46: Lagging edge model | F46: =F17/F27 -> 2.2222222 | G46: =G17/G27 -> 1 | H46: =H17/H27 -> 1 | I46: =I17/I27 -> 1 | J46: =J17/J27 -> 1
B47: Openweight model | F47: =F27/F27 -> 1 | G47: =G27/G27 -> 1 | H47: =H27/H27 -> 1 | I47: =I27/I27 -> 1 | J47: =J27/J27 -> 1
...

Sheet OpenAI
D1: 2024 | E1: 2025 | F1: 2026 | G1: 2027 | H1: 2028 | I1: 2029 | J1: 2030
B2: Capacity (GW)
C3: Amazon NVDA | G3: =300000/'GB300 '!E52 -> 0.675 | H3: =G3 -> 0.675 | I3: =H3 -> 0.675 | J3: =I3 -> 0.675
C4: Amazon Trainium | G4: 2 | H4: 2 | I4: 2 | J4: 2
C5: Oracle NVDA | G5: =Oracle!G5 -> 4 | H5: =Oracle!H5 -> 4.5 | I5: =Oracle!I5 -> 4.5 | J5: =Oracle!J5 -> 4.5
C6: Microsoft NVDA | G6: 5 | H6: =G6 -> 5 | I6: =H6 -> 5 | J6: =I6 -> 5
C7: Other | G7: 0 | H7: 0 | I7: 0 | J7: 0
B8: Total | F8: 3 | G8: =SUM(G3:G7) -> 11.675 | H8: =SUM(H3:H7) -> 12.175 | I8: =SUM(I3:I7) -> 12.175 | J8: =SUM(J3:J7) -> 12.175
B10: Allocation
C11: Leading edge | E11: 0.1 | F11: 0.1 | G11: 0.3 | H11: 0.1 | I11: 0.1 | J11: 0.1
C12: Lagging edge | E12: 0.1 | F12: 0.1 | G12: 0.1 | H12: 0.1 | I12: 0.1 | J12: 0.1
C13: Open weight | E13: =1-E14-E12-E11 -> 0.6 | F13: =1-F14-F12-F11 -> 0.6 | G13: =1-G14-G12-G11 -> 0.4 | H13: =1-H14-H12-H11 -> 0.6 | I13: =1-I14-I12-I11 -> 0.6 | J13: =1-J14-J12-J11 -> 0.6
C14: Training | E14: 0.2 | F14: 0.2 | G14: 0.2 | H14: 0.2 | I14: 0.2 | J14: 0.2
B16: Revenue
C17: Leading edge | G17: =G8*G11*'Model unit economics'!F11*1000 -> 73636.56
C18: Lagging edge | G18: =G8*G12*'Model unit economics'!F21*1000 -> 14727.312
C19: Open weight | G19: =G8*G13*'Model unit economics'!F31*1000 -> 53018.323
B20: Total | G20: =SUM(G17:G19) -> 141382.2
B22: Costs
C23: Amazon | F23: =Amazon!F60+Amazon!F61 -> 0 | G23: =Amazon!G60+Amazon!G61 -> 17928.571 | H23: =Amazon!H60+Amazon!H61 -> 17928.571 | I23: =Amazon!I60+Amazon!I61 -> 17928.571 | J23: =Amazon!J60+Amazon!J61 -> 17928.571
C24: Oracle | E24: =Oracle!E11 -> 0 | F24: =Oracle!F11 -> 22222.222 | G24: =Oracle!G11 -> 44444.444 | H24: =Oracle!H11 -> 50000 | I24: =Oracle!I11 -> 50000 | J24: =Oracle!J11 -> 50000
C25: Microsoft | F25: =Microsoft!F3 -> 41666.667 | G25: =Microsoft!G3 -> 41666.667 | H25: =Microsoft!H3 -> 41666.667 | I25: =Microsoft!I3 -> 41666.667 | J25: =Microsoft!J3 -> 41666.667
C26: Other
B27: Total | F27: =SUM(F23:F26) -> 63888.889 | G27: =SUM(G23:G26) -> 104039.68 | H27: =SUM(H23:H26) -> 109595.24 | I27: =SUM(I23:I26) -> 109595.24 | J27: =SUM(J23:J26) -> 109595.24
G28: =G20-G27 -> 37342.513
B29: Blackwell | F29: ='GB300 '!E52 -> 444444.44
B30: Rental rate | F30: ='Rental rates'!D3 -> 5.65
B31: Hours per year | F31: =24*365 -> 8760
B32: Rental cost ($m) | F32: =F29*F30*F31/1000000 -> 21997.333
B34: Openweight model
B35: Tokens per second | F35: 10000
B36: Seconds per year | F36: =60*60*F31 -> 31536000
B37: Tokens per year (millions) | F37: =F35*F36/1000000 -> 315360
B38: Blended token price | F38: 2
B39: Token revenue per chip | F39: =F37*F38 -> 630720
B40: Blackwells | F40: =F29 -> 444444.44
B41: Annual revneue (bn) | F41: =F39*F40/1000000000 -> 280.32

Sheet Oracle
D1: 2024 | E1: 2025 | F1: 2026 | G1: 2027 | H1: 2028 | I1: 2029 | J1: 2030
B2: Oracle
B3: Installed Power (GW) | E3: 0 | F3: 2 | G3: 2 | H3: 0.5 | I3: 0 | J3: 0
B4: Installed chips | F4: =F3*'GB300 '!E52 -> 888888.89 | G4: =G3*'Vera Rubin'!$E$52 -> 598752.6 | H4: =H3*'Vera Rubin'!$E$52 -> 149688.15 | I4: =I3*'Vera Rubin'!$E$52 -> 0 | J4: =J3*'Vera Rubin'!$E$52 -> 0
B5: Total Power (GW) | E5: 0 | F5: =E3+F3 -> 2 | G5: =F5+G3 -> 4 | H5: =G5+H3 -> 4.5 | I5: =H5+I3 -> 4.5 | J5: =I5+J3 -> 4.5
B6: Blackwell chips | F6: =F4 -> 888888.89
B7: Rubin chips | G7: =G4 -> 598752.6 | H7: =G7+H4 -> 748440.75
B9: Spend per GW | D9: =50000/4.5 -> 11111.111
B11: Spend | E11: =$D$9*E5 -> 0 | F11: =$D$9*F5 -> 22222.222 | G11: =$D$9*G5 -> 44444.444 | H11: =$D$9*H5 -> 50000 | I11: =H11 -> 50000 | J11: =I11 -> 50000

Sheet Anthropic

Sheet Amazon
D1: 2024 | E1: 2025 | F1: 2026 | G1: 2027 | H1: 2028 | I1: 2029 | J1: 2030
B3: AI Capex
B5: Chip installed base
B7: Trainium
B8: Beginning installed | E8: =D11 -> 1000000 | F8: =E11 -> 2485000 | G8: =F11 -> 4185000 | H8: =G11 -> 6565000
C9: Added | E9: ='Chip sales'!F70 -> 1485000 | F9: ='Chip sales'!G70 -> 1700000 | G9: ='Chip sales'!H70 -> 2380000 | H9: ='Chip sales'!I70 -> 3000000
C10: Retired | E10: 0 | F10: 0 | G10: 0 | H10: 0
B11: End installed | D11: 1000000 | E11: =SUM(E8:E10) -> 2485000 | F11: =SUM(F8:F10) -> 4185000 | G11: =SUM(G8:G10) -> 6565000 | H11: =SUM(H8:H10) -> 9565000
B13: Hopper
B14: Beginning installed | E14: =D17 -> 200000 | F14: =E17 -> 270000 | G14: =F17 -> 270000 | H14: =G17 -> 270000
C15: Added | E15: ='Chip sales'!F8 -> 70000 | F15: ='Chip sales'!G8 -> 0 | G15: ='Chip sales'!H8 -> 0 | H15: ='Chip sales'!I8 -> 0
C16: Retired | E16: 0 | F16: 0 | G16: 0 | H16: 0
B17: End installed | D17: 200000 | E17: =SUM(E14:E16) -> 270000 | F17: =SUM(F14:F16) -> 270000 | G17: =SUM(G14:G16) -> 270000 | H17: =SUM(H14:H16) -> 270000
B19: Blackwell
B20: Beginning installed | E20: =D23 -> 200000 | F20: =E23 -> 480000 | G20: =F23 -> 1000000 | H20: =G23 -> 1187500
C21: Added | E21: ='Chip sales'!F4+'Chip sales'!F7 -> 280000 | F21: ='Chip sales'!G4+'Chip sales'!G7 -> 520000 | G21: ='Chip sales'!H4+'Chip sales'!H7 -> 187500 | H21: ='Chip sales'!I4+'Chip sales'!I7 -> 0
C22: Retired | E22: 0 | F22: 0 | G22: 0 | H22: 0
B23: End installed | D23: 200000 | E23: =SUM(E20:E22) -> 480000 | F23: =SUM(F20:F22) -> 1000000 | G23: =SUM(G20:G22) -> 1187500 | H23: =SUM(H20:H22) -> 1187500
B25: Rubin
B26: Beginning installed | E26: =D29 -> 0 | F26: =E29 -> 0 | G26: =F29 -> 130000 | H26: =G29 -> 692500
C27: Added | E27: ='Chip sales'!F5+'Chip sales'!F6 -> 0 | F27: ='Chip sales'!G5+'Chip sales'!G6 -> 130000 | G27: ='Chip sales'!H5+'Chip sales'!H6 -> 562500 | H27: ='Chip sales'!I5+'Chip sales'!I6 -> 600000
C28: Retired | E28: 0 | F28: 0 | G28: 0 | H28: 0
B29: End installed | D29: 0 | E29: =SUM(E26:E28) -> 0 | F29: =SUM(F26:F28) -> 130000 | G29: =SUM(G26:G28) -> 692500 | H29: =SUM(H26:H28) -> 1292500
B31: Open AI NVDA chips | G31: 300000 | H31: 300000
B32: Open AI trainium chips | G32: =Trainium3!E53*2 -> 1538461.5 | H32: =G32 -> 1538461.5 | K32: OpenAI and Amazon announce strategic partnership | OpenAI
B33: Implied NVDA rental rate per chip per hour | G33: =(G60*1000000/G31)/(8760*0.8) -> 2.5820831 | H33: =(H60*1000000/H31)/(8760*0.8) -> 2.5820831
B34: Implied trainium rental rate per chip per hour | G34: =(G61*1000000/G32)/(8760*0.8) -> 1.1593893 | H34: =(H61*1000000/H32)/(8760*0.8) -> 1.1593893
B36: NVDA IRR | H36: =IRR(K36:S36) -> 0.063221659 | K36: =-'GB300 '!E67*Amazon!$G$31/'GB300 '!$E$52 -> -30218.962 | L36: =G60-500 -> 4928.5714 | M36: =L36 -> 4928.5714 | N36: =M36 -> 4928.5714 | O36: =N36 -> 4928.5714 | P36: =O36 -> 4928.5714 | Q36: =P36 -> 4928.5714 | R36: =Q36 -> 4928.5714 | S36: =R36 -> 4928.5714
B37: Trainium IRR | H37: =IRR(K37:S37) -> 0.20323199 | K37: =-Trainium3!E68*2 -> -41805.481 | L37: =H61-1500 -> 11000 | M37: =L37 -> 11000 | N37: =M37 -> 11000 | O37: =N37 -> 11000 | P37: =O37 -> 11000 | Q37: =P37 -> 11000 | R37: =Q37 -> 11000 | S37: =R37 -> 11000
B39: Anthropic trainium chips | G39: =Trainium3!E53*3 -> 2307692.3 | H39: =Trainium3!E53*5 -> 3846153.8
B41: Remaining trainium chips | G41: =G11-G32-G39 -> 2718846.2 | H41: =H11-H32-H39 -> 4180384.6
B42: Reamining hopper chips | G42: =G17 -> 270000 | H42: =H17 -> 270000
B43: Remaining blackwell chips | G43: =G23-G31 -> 887500 | H43: =H23-H31 -> 887500
B44: Remaining rubin chips | G44: =G29 -> 692500 | H44: =H29 -> 1292500
B46: Trainium rental rates | H46: 1.5
B47: Hopper rental rates | H47: 2
B48: Blackwell rental rates | H48: 2.5
B49: Rubin rental rates | H49: 2.5
B51: Trainium rental rates | H51: =H46*8760*0.8*AVERAGE(G41:H41)/1000000 -> 36262.357
B52: Hopper rental rates | H52: =H47*8760*0.8*AVERAGE(G42:H42)/1000000 -> 3784.32
...

Sheet Google

Sheet Microsoft
D1: 2024 | E1: 2025 | F1: 2026 | G1: 2027 | H1: 2028 | I1: 2029 | J1: 2030
B3: OpenAI contract | F3: =250000/6 -> 41666.667 | G3: =250000/6 -> 41666.667 | H3: =250000/6 -> 41666.667 | I3: =250000/6 -> 41666.667 | J3: =250000/6 -> 41666.667
B4: Assumed Rental price | F4: =Amazon!G33 -> 2.5820831 | G4: =F4 -> 2.5820831 | H4: =G4 -> 2.5820831 | I4: =H4 -> 2.5820831 | J4: =I4 -> 2.5820831
F5: =F4*Conversion!C9*1000 -> 8042.328 | G5: =F5 -> 8042.328 | H5: =G5 -> 8042.328 | I5: =H5 -> 8042.328 | J5: =I5 -> 8042.328
F6: =F3/F5 -> 5.1809211 | G6: =G3/G5 -> 5.1809211 | H6: =H3/H5 -> 5.1809211 | I6: =I3/I5 -> 5.1809211 | J6: =J3/J5 -> 5.1809211
F7: ='GB300 '!E52*F6 -> 2302631.6

Sheet Neoclouds
